import { createError } from "../utils/error.js"
import { createSuccess } from "../utils/success.js";
import User from "../models/user.js"

export const getAllUsers = async (req,res,next)=>{
    try {
        const users = await User.find();
        return res.status(200).send(users)
        //return next(createSuccess(200,"All users",users))
    } catch (error) {
        return next(createError(500,"Internal Server Error"))
    }
}

export const getUserById = async (req,res,next)=>{
    try {
        const user = await User.findById(req.params.id)
        if(!user)
            return next(createError(404,"User not found"))
            return res.status(200).send(user)
            //return next(createSuccess(200,"Single user",user))
    } catch (error) {
        return next(createError(500,"Internal Server Error"))
    }
}